Workbook

Sheet Ventas
A1: DATE | B1: CUSTOMER ID | C1: PRODUCT | D1: LOCATION | E1: ACCOUNT INCOME | F1: SALES COMMISSION | G1: SUBTOTAL | H1: INCOME TAX (ISR) | I1: VAT (IVA) | J1: SHIPPING | K1: TOTAL PROFIT | L1: Year | M1: Quarter
A2: 45451 | B2: Customer 1 | C2: MARTIAN PIN | D2: Baja California | E2: 86.33 | F2: 37.95 | G2: 74.42 | H2: 0.74 | I2: 5.95 | J2: 0 | K2: 41.68 | L2: =YEAR(A2) -> 2024 | M2: =ROUNDUP(MONTH(A2)/3,0) -> 2
A3: 45453 | B3: Customer 2 | C3: HQ3 STABILIZER | D3: Quintana Roo | E3: 1299 | F3: 188.36 | G3: 1119.83 | H3: 11.2 | I3: 89.59 | J3: 95 | K3: 914.86 | L3: =YEAR(A3) -> 2024 | M3: =ROUNDUP(MONTH(A3)/3,0) -> 2
A4: 45457 | B4: Customer 3 | C4: RED GUITAR PIN | D4: Tamaulipas | E4: 86.33 | F4: 37.95 | G4: 74.42 | H4: 0.74 | I4: 5.95 | J4: 0 | K4: 41.68 | L4: =YEAR(A4) -> 2024 | M4: =ROUNDUP(MONTH(A4)/3,0) -> 2
A5: 45459 | B5: Customer 4 | C5: HQ3 STABILIZER | D5: Michoacán | E5: 1299 | F5: 188.36 | G5: 1119.83 | H5: 11.2 | I5: 89.59 | J5: 95 | K5: 914.86 | L5: =YEAR(A5) -> 2024 | M5: =ROUNDUP(MONTH(A5)/3,0) -> 2
A6: 45461 | B6: Customer 5 | C6: AOCHUAN Smart XE STABILIZER | D6: Baja California | E6: 1467 | F6: 212.72 | G6: 1264.66 | H6: 12.65 | I6: 101.17 | J6: 83.4 | K6: 1057.07 | L6: =YEAR(A6) -> 2024 | M6: =ROUNDUP(MONTH(A6)/3,0) -> 2
A7: 45463 | B7: Customer 6 | C7: AOCHUAN Smart XE STABILIZER | D7: Guanajuato | E7: 1699 | F7: 246.36 | G7: 1464.66 | H7: 14.65 | I7: 117.17 | J7: 69.5 | K7: 1251.33 | L7: =YEAR(A7) -> 2024 | M7: =ROUNDUP(MONTH(A7)/3,0) -> 2
A8: 45467 | B8: Customer 7 | C8: AOCHUAN Smart XE STABILIZER | D8: Nuevo León | E8: 1899 | F8: 284.85 | G8: 1637.07 | H8: 16.37 | I8: 130.97 | J8: 69.5 | K8: 1397.31 | L8: =YEAR(A8) -> 2024 | M8: =ROUNDUP(MONTH(A8)/3,0) -> 2
A9: 45467 | B9: Customer 8 | C9: RORETA 3C STABILIZER | D9: State of Mexico | E9: 300 | F9: 0 | G9: 0 | H9: 0 | I9: 0 | J9: 0 | K9: 300 | L9: =YEAR(A9) -> 2024 | M9: =ROUNDUP(MONTH(A9)/3,0) -> 2
A10: 45467 | B10: Customer 8 | C10: RORETA 3C STABILIZER | D10: State of Mexico | E10: 300 | F10: 0 | G10: 0 | H10: 0 | I10: 0 | J10: 0 | K10: 300 | L10: =YEAR(A10) -> 2024 | M10: =ROUNDUP(MONTH(A10)/3,0) -> 2
A11: 45470 | B11: Customer 9 | C11: HQ3 STABILIZER | D11: Coahuila | E11: 1199 | F11: 173.86 | G11: 1033.62 | H11: 10.34 | I11: 82.69 | J11: 95 | K11: 837.12 | L11: =YEAR(A11) -> 2024 | M11: =ROUNDUP(MONTH(A11)/3,0) -> 2
A12: 45472 | B12: Customer 10 | C12: AOCHUAN Smart XE STABILIZER | D12: Sonora | E12: 1699 | F12: 246.36 | G12: 1464.66 | H12: 14.65 | I12: 117.17 | J12: 69.5 | K12: 1251.33 | L12: =YEAR(A12) -> 2024 | M12: =ROUNDUP(MONTH(A12)/3,0) -> 2
A13: 45473 | B13: Customer 11 | C13: 18/PIECE STAINLESS STEEL MANICURE & PEDICURE KIT | D13: State of Mexico | E13: 200 | F13: 0 | G13: 0 | H13: 0 | I13: 0 | J13: 0 | K13: 200 | L13: =YEAR(A13) -> 2024 | M13: =ROUNDUP(MONTH(A13)/3,0) -> 2
... A950: 46225 | B950: Customer 420 | C950: BLACK FRONT SNORKEL | D950: Veracruz | E950: 351.2 | F950: 68.48 | G950: 302.76 | H950: 7.57 | I950: 24.22 | J950: 67.6 | K950: 183.33 | L950: =YEAR(A950) -> 2026 | M950: =ROUNDUP(MONTH(A950)/3,0) -> 3

Sheet Análisis
A1: KPIs PRINCIPALES
A3: Ingreso total | B3: =SUM(Ventas!$E$2:$E$950) -> 857992.67
A4: Utilidad total | B4: =SUM(Ventas!$K$2:$K$950) -> 605336.55
A5: Numero de ventas | B5: =COUNTA(Ventas!$B$2:$B$950) -> 949
A6: Ticket promedio | B6: =B3/B5 -> 904.10187
A7: Utilidad prom. por venta | B7: =B4/B5 -> 637.86781
A8: Margen de utilidad | B8: =B4/B3 -> 0.70552648
A10: UTILIDAD POR AÑO
A11: Año | B11: Utilidad | C11: Crecimiento vs. año anterior
A12: 2024 | B12: =SUMIFS(Ventas!$K$2:$K$950,Ventas!$L$2:$L$950,2024) -> 176150.18 | C12: -
A13: 2025 | B13: =SUMIFS(Ventas!$K$2:$K$950,Ventas!$L$2:$L$950,2025) -> 303622.41 | C13: =(B13-B12)/B12 -> 0.72365654
A14: 2026 | B14: =SUMIFS(Ventas!$K$2:$K$950,Ventas!$L$2:$L$950,2026) -> 125563.96 | C14: =(B14-B13)/B13 -> -0.586447
A15: Nota: 2026 con datos parciales (hasta la ultima fecha registrada).
A17: UTILIDAD POR TRIMESTRE
A18: Trimestre | B18: Utilidad
A19: 24-T2 | B19: =SUMIFS(Ventas!$K$2:$K$950,Ventas!$L$2:$L$950,2024,Ventas!$M$2:$M$950,2) -> 9853.42
A20: 24-T3 | B20: =SUMIFS(Ventas!$K$2:$K$950,Ventas!$L$2:$L$950,2024,Ventas!$M$2:$M$950,3) -> 89487.42
A21: 24-T4 | B21: =SUMIFS(Ventas!$K$2:$K$950,Ventas!$L$2:$L$950,2024,Ventas!$M$2:$M$950,4) -> 76809.34
A22: 25-T1 | B22: =SUMIFS(Ventas!$K$2:$K$950,Ventas!$L$2:$L$950,2025,Ventas!$M$2:$M$950,1) -> 85683.61
A23: 25-T2 | B23: =SUMIFS(Ventas!$K$2:$K$950,Ventas!$L$2:$L$950,2025,Ventas!$M$2:$M$950,2) -> 66926.95
A24: 25-T3 | B24: =SUMIFS(Ventas!$K$2:$K$950,Ventas!$L$2:$L$950,2025,Ventas!$M$2:$M$950,3) -> 79489.08
A25: 25-T4 | B25: =SUMIFS(Ventas!$K$2:$K$950,Ventas!$L$2:$L$950,2025,Ventas!$M$2:$M$950,4) -> 71522.77
A26: 26-T1 | B26: =SUMIFS(Ventas!$K$2:$K$950,Ventas!$L$2:$L$950,2026,Ventas!$M$2:$M$950,1) -> 71102.7
A27: 26-T2 | B27: =SUMIFS(Ventas!$K$2:$K$950,Ventas!$L$2:$L$950,2026,Ventas!$M$2:$M$950,2) -> 47026.69
A28: 26-T3 | B28: =SUMIFS(Ventas!$K$2:$K$950,Ventas!$L$2:$L$950,2026,Ventas!$M$2:$M$950,3) -> 7434.57
A30: UTILIDAD POR PRODUCTO (ordenado de mayor a menor)
A31: Producto | B31: Utilidad | C31: % del total
A32: AOCHUAN Smart XE STABILIZER | B32: =SUMIFS(Ventas!$K$2:$K$950,Ventas!$C$2:$C$950,"AOCHUAN Smart XE STABILIZER") -> 247015.94 | C32: =B32/$B$4 -> 0.40806381
A33: AOCHUAN Smart XE STABILIZER WITH LIGHT | B33: =SUMIFS(Ventas!$K$2:$K$950,Ventas!$C$2:$C$950,"AOCHUAN Smart XE STABILIZER WITH LIGHT") -> 95768.92 | C33: =B33/$B$4 -> 0.15820773
A34: AOCHUAN X PRO STABILIZER (GRAY) | B34: =SUMIFS(Ventas!$K$2:$K$950,Ventas!$C$2:$C$950,"AOCHUAN X PRO STABILIZER (GRAY)") -> 62622.21 | C34: =B34/$B$4 -> 0.10345024
A35: AOCHUAN X PRO STABILIZER (BLACK) | B35: =SUMIFS(Ventas!$K$2:$K$950,Ventas!$C$2:$C$950,"AOCHUAN X PRO STABILIZER (BLACK)") -> 50756.98 | C35: =B35/$B$4 -> 0.083849191
A36: AOCHUAN FILL LIGHT | B36: =SUMIFS(Ventas!$K$2:$K$950,Ventas!$C$2:$C$950,"AOCHUAN FILL LIGHT") -> 20298.49 | C36: =B36/$B$4 -> 0.03353257
A37: BLACK FRONT SNORKEL | B37: =SUMIFS(Ventas!$K$2:$K$950,Ventas!$C$2:$C$950,"BLACK FRONT SNORKEL") -> 10380.84 | C37: =B37/$B$4 -> 0.017148874
A38: S5B STABILIZER | B38: =SUMIFS(Ventas!$K$2:$K$950,Ventas!$C$2:$C$950,"S5B STABILIZER") -> 9903.82 | C38: =B38/$B$4 -> 0.016360849
A39: BLUE FRONT SNORKEL | B39: =SUMIFS(Ventas!$K$2:$K$950,Ventas!$C$2:$C$950,"BLUE FRONT SNORKEL") -> 9598.31 | C39: =B39/$B$4 -> 0.015856155
A40: L7Cpro Plus + AI STABILIZER | B40: =SUMIFS(Ventas!$K$2:$K$950,Ventas!$C$2:$C$950,"L7Cpro Plus + AI STABILIZER") -> 8879.73 | C40: =B40/$B$4 -> 0.01466908
A41: AQUA GREEN FRONT SNORKEL | B41: =SUMIFS(Ventas!$K$2:$K$950,Ventas!$C$2:$C$950,"AQUA GREEN FRONT SNORKEL") -> 7719.29 | C41: =B41/$B$4 -> 0.012752063
A42: S5B PRO STABILIZER | B42: =SUMIFS(Ventas!$K$2:$K$950,Ventas!$C$2:$C$950,"S5B PRO STABILIZER") -> 6842.07 | C42: =B42/$B$4 -> 0.011302919
A43: AOCHUAN X PRO STABILIZER (GRAY) WITH LIGHT | B43: =SUMIFS(Ventas!$K$2:$K$950,Ventas!$C$2:$C$950,"AOCHUAN X PRO STABILIZER (GRAY) WITH LIGHT") -> 6762.86 | C43: =B43/$B$4 -> 0.011172066
A44: HQ3 STABILIZER | B44: =SUMIFS(Ventas!$K$2:$K$950,Ventas!$C$2:$C$950,"HQ3 STABILIZER") -> 6159.09 | C44: =B44/$B$4 -> 0.010174654
...

Sheet Dashboard
B2: DASHBOARD DE VENTAS
B4: INGRESO TOTAL | D4: UTILIDAD TOTAL | F4: NUMERO DE VENTAS | H4: TICKET PROMEDIO | J4: MARGEN DE UTILIDAD
B5: =Análisis!B3 -> 857992.67 | D5: =Análisis!B4 -> 605336.55 | F5: =Análisis!B5 -> 949 | H5: =Análisis!B6 -> 904.10187 | J5: =Análisis!B8 -> 0.70552648
